Workbook

Sheet Report
A1: Membership Report - select a product and month
A3: Product | B3: MA-HMO | D3: Yellow cells are dropdowns (data validation). All other values are live formulas.
A4: Month | B4: 46266
A5: Members | B5: =SUMIFS(Data!$D:$D,Data!$B:$B,$B$3,Data!$A:$A,$B$4) -> 88795
A6: Members, same month last year | B6: =SUMIFS(Data!$D:$D,Data!$B:$B,$B$3,Data!$A:$A,EDATE($B$4,-12)) -> 83183
A7: YoY change | B7: =B5-B6 -> 5612
A8: YoY % | B8: =IFERROR(B7/B6,"n/a") -> 0.067465708
A9: Gross adds | B9: =SUMIFS(Data!$E:$E,Data!$B:$B,$B$3,Data!$A:$A,$B$4) -> 1072
A10: Terminations | B10: =SUMIFS(Data!$F:$F,Data!$B:$B,$B$3,Data!$A:$A,$B$4) -> 465
A11: Line of business (INDEX-MATCH) | B11: =INDEX(Products!$B:$B,MATCH($B$3,Products!$A:$A,0)) -> Medicare Advantage
A12: Owner team (XLOOKUP) | B12: =_xlfn.XLOOKUP($B$3,Products!$A:$A,Products!$C:$C,"Not found") -> #NAME? | D12: XLOOKUP needs Excel 2021 or Microsoft 365; VLOOKUP and INDEX-MATCH give the same answer.
A13: Owner team (VLOOKUP) | B13: =VLOOKUP($B$3,Products!$A:$C,3,FALSE) -> Government Markets
A14: 2026 budget | B14: =SUMIFS(Budget!$D:$D,Budget!$B:$B,$B$3,Budget!$A:$A,$B$4) -> 92084
A15: Variance to budget % | B15: =IF(B14=0,"no budget",(B5-B14)/B14) -> -0.035717388

Sheet Pivot
A1: PivotTable: average monthly members by product and year (filter by line of business) | B1: (All)
A3: Avg monthly members | B3: Column Labels
A4: Row Labels | B4: 2021 | C4: 2022 | D4: 2023 | E4: 2024 | F4: 2025 | G4: 2026 | H4: Grand Total
A5: ACA Individual | B5: 37310.083 | C5: 39616.167 | D5: 42017.167 | E5: 44914.75 | F5: 47588.5 | G5: 44521.333 | H5: 42580.464
A6: Large Group | B6: 215024.42 | C6: 220478 | D6: 225301.33 | E6: 230486.17 | F6: 237063.75 | G6: 243110.89 | H6: 227945.54
A7: MA-HMO | B7: 65293.333 | C7: 69564.917 | D7: 74322 | E7: 78766.333 | F7: 83425.917 | G7: 88287.667 | H7: 76102.304
A8: MA-PPO | B8: 43525.667 | C8: 47349.167 | D8: 51647.167 | E8: 56401.917 | F8: 61234.5 | G8: 67570.667 | H8: 54058.507
A9: PDP | B9: 28267.75 | C9: 28198.583 | D9: 28229.417 | E9: 28371.333 | F9: 28553.25 | G9: 28559 | H9: 28354.71
A10: Small Group | B10: 54503.417 | C10: 54449.25 | D10: 54672.667 | E10: 54748.667 | F10: 54315.917 | G10: 54248.333 | H10: 54500.203
A11: Grand Total | B11: 73987.444 | C11: 76609.347 | D11: 79364.958 | E11: 82281.528 | F11: 85363.639 | G11: 87716.315 | H11: 80590.287

Sheet Data
A1: month | B1: product | C1: line_of_business | D1: members | E1: gross_adds | F1: terminations | G1: net_change | H1: mom_pct | I1: yoy_pct | J1: year
A2: 44197 | B2: ACA Individual | C2: Commercial Individual | D2: 37870 | E2: 3339 | F2: 0 | J2: 2021
A3: 44228 | B3: ACA Individual | C3: Commercial Individual | D3: 37434 | E3: 357 | F3: 793 | G3: -436 | H3: -1.15 | J3: 2021
A4: 44256 | B4: ACA Individual | C4: Commercial Individual | D4: 36786 | E4: 391 | F4: 1039 | G4: -648 | H4: -1.73 | J4: 2021
A5: 44287 | B5: ACA Individual | C5: Commercial Individual | D5: 36854 | E5: 530 | F5: 462 | G5: 68 | H5: 0.18 | J5: 2021
A6: 44317 | B6: ACA Individual | C6: Commercial Individual | D6: 37052 | E6: 541 | F6: 343 | G6: 198 | H6: 0.54 | J6: 2021
A7: 44348 | B7: ACA Individual | C7: Commercial Individual | D7: 37161 | E7: 458 | F7: 349 | G7: 109 | H7: 0.29 | J7: 2021
A8: 44378 | B8: ACA Individual | C8: Commercial Individual | D8: 37277 | E8: 423 | F8: 307 | G8: 116 | H8: 0.31 | J8: 2021
A9: 44409 | B9: ACA Individual | C9: Commercial Individual | D9: 37434 | E9: 521 | F9: 364 | G9: 157 | H9: 0.42 | J9: 2021
A10: 44440 | B10: ACA Individual | C10: Commercial Individual | D10: 37508 | E10: 395 | F10: 321 | G10: 74 | H10: 0.2 | J10: 2021
A11: 44470 | B11: ACA Individual | C11: Commercial Individual | D11: 37365 | E11: 374 | F11: 561 | G11: -143 | H11: -0.38 | J11: 2021
A12: 44501 | B12: ACA Individual | C12: Commercial Individual | D12: 37460 | E12: 456 | F12: 361 | G12: 95 | H12: 0.25 | J12: 2021
A13: 44531 | B13: ACA Individual | C13: Commercial Individual | D13: 37520 | E13: 426 | F13: 366 | G13: 60 | H13: 0.16 | J13: 2021
A14: 44562 | B14: ACA Individual | C14: Commercial Individual | D14: 40579 | E14: 3483 | F14: 424 | G14: 3059 | H14: 8.15 | I14: 7.15 | J14: 2022
A15: 44593 | B15: ACA Individual | C15: Commercial Individual | D15: 39929 | E15: 407 | F15: 1057 | G15: -650 | H15: -1.6 | I15: 6.67 | J15: 2022
A16: 44621 | B16: ACA Individual | C16: Commercial Individual | D16: 39203 | E16: 413 | F16: 1139 | G16: -726 | H16: -1.82 | I16: 6.57 | J16: 2022
A17: 44652 | B17: ACA Individual | C17: Commercial Individual | D17: 39331 | E17: 539 | F17: 411 | G17: 128 | H17: 0.33 | I17: 6.72 | J17: 2022
A18: 44682 | B18: ACA Individual | C18: Commercial Individual | D18: 39421 | E18: 469 | F18: 381 | G18: 90 | H18: 0.23 | I18: 6.39 | J18: 2022
A19: 44713 | B19: ACA Individual | C19: Commercial Individual | D19: 39643 | E19: 479 | F19: 257 | G19: 222 | H19: 0.56 | I19: 6.68 | J19: 2022
A20: 44743 | B20: ACA Individual | C20: Commercial Individual | D20: 39416 | E20: 401 | F20: 628 | G20: -227 | H20: -0.57 | I20: 5.74 | J20: 2022
A21: 44774 | B21: ACA Individual | C21: Commercial Individual | D21: 39443 | E21: 402 | F21: 375 | G21: 27 | H21: 0.07 | I21: 5.37 | J21: 2022
A22: 44805 | B22: ACA Individual | C22: Commercial Individual | D22: 39431 | E22: 437 | F22: 449 | G22: -12 | H22: -0.03 | I22: 5.13 | J22: 2022
A23: 44835 | B23: ACA Individual | C23: Commercial Individual | D23: 39572 | E23: 556 | F23: 415 | G23: 141 | H23: 0.36 | I23: 5.91 | J23: 2022
A24: 44866 | B24: ACA Individual | C24: Commercial Individual | D24: 39713 | E24: 501 | F24: 360 | G24: 141 | H24: 0.36 | I24: 6.01 | J24: 2022
A25: 44896 | B25: ACA Individual | C25: Commercial Individual | D25: 39713 | E25: 468 | F25: 494 | G25: 0 | H25: 0 | I25: 5.84 | J25: 2022
... A70: 46266 | B70: ACA Individual | C70: Commercial Individual | D70: 43291 | E70: 442 | F70: 655 | G70: -213 | H70: -0.49 | I70: -8.86 | J70: 2026
A71: 44197 | B71: Large Group | C71: Commercial Group | D71: 214495 | E71: 6873 | F71: 0 | J71: 2021
A72: 44228 | B72: Large Group | C72: Commercial Group | D72: 213152 | E72: 2135 | F72: 3478 | G72: -1343 | H72: -0.63 | J72: 2021
A73: 44256 | B73: Large Group | C73: Commercial Group | D73: 215285 | E73: 3264 | F73: 1190 | G73: 2133 | H73: 1 | J73: 2021
A74: 44287 | B74: Large Group | C74: Commercial Group | D74: 215166 | E74: 2106 | F74: 2225 | G74: -119 | H74: -0.06 | J74: 2021
A75: 44317 | B75: Large Group | C75: Commercial Group | D75: 215426 | E75: 1967 | F75: 1707 | G75: 260 | H75: 0.12 | J75: 2021
A76: 44348 | B76: Large Group | C76: Commercial Group | D76: 214509 | E76: 2250 | F76: 3167 | G76: -917 | H76: -0.43 | J76: 2021
A77: 44378 | B77: Large Group | C77: Commercial Group | D77: 214763 | E77: 2241 | F77: 1987 | G77: 254 | H77: 0.12 | J77: 2021
A78: 44409 | B78: Large Group | C78: Commercial Group | D78: 215967 | E78: 2626 | F78: 1588 | G78: 1204 | H78: 0.56 | J78: 2021
A79: 44440 | B79: Large Group | C79: Commercial Group | D79: 216418 | E79: 2341 | F79: 1966 | G79: 451 | H79: 0.21 | J79: 2021
A80: 44470 | B80: Large Group | C80: Commercial Group | D80: 215446 | E80: 2155 | F80: 3127 | G80: -972 | H80: -0.45 | J80: 2021
A81: 44501 | B81: Large Group | C81: Commercial Group | D81: 214753 | E81: 2110 | F81: 2803 | G81: -693 | H81: -0.32 | J81: 2021
A82: 44531 | B82: Large Group | C82: Commercial Group | D82: 214913 | E82: 2337 | F82: 2177 | G82: 160 | H82: 0.07 | J82: 2021
A83: 44562 | B83: Large Group | C83: Commercial Group | D83: 219119 | E83: 6431 | F83: 2225 | G83: 4206 | H83: 1.96 | I83: 2.16 | J83: 2022
A84: 44593 | B84: Large Group | C84: Commercial Group | D84: 219366 | E84: 2581 | F84: 2334 | G84: 247 | H84: 0.11 | I84: 2.92 | J84: 2022
...

Sheet Products
A1: product | B1: line_of_business | C1: owner_team
A2: MA-HMO | B2: Medicare Advantage | C2: Government Markets
A3: MA-PPO | B3: Medicare Advantage | C3: Government Markets
A4: PDP | B4: Medicare Part D | C4: Government Markets
A5: ACA Individual | B5: Commercial Individual | C5: Commercial Sales
A6: Large Group | B6: Commercial Group | C6: Commercial Sales
A7: Small Group | B7: Commercial Group | C7: Commercial Sales

Sheet Budget
A1: month | B1: product | C1: actual_members | D1: budget_members | E1: variance | F1: variance_pct
A2: 46023 | B2: ACA Individual | C2: 46990 | D2: 52373 | E2: =C2-D2 -> -5383 | F2: =IFERROR(E2/D2,0) -> -0.10278197
A3: 46054 | B3: ACA Individual | C3: 45746 | D3: 52478 | E3: =C3-D3 -> -6732 | F3: =IFERROR(E3/D3,0) -> -0.12828233
A4: 46082 | B4: ACA Individual | C4: 44810 | D4: 52583 | E4: =C4-D4 -> -7773 | F4: =IFERROR(E4/D4,0) -> -0.14782344
A5: 46113 | B5: ACA Individual | C5: 44337 | D5: 52688 | E5: =C5-D5 -> -8351 | F5: =IFERROR(E5/D5,0) -> -0.15849909
A6: 46143 | B6: ACA Individual | C6: 44104 | D6: 52792 | E6: =C6-D6 -> -8688 | F6: =IFERROR(E6/D6,0) -> -0.16457039
A7: 46174 | B7: ACA Individual | C7: 44119 | D7: 52897 | E7: =C7-D7 -> -8778 | F7: =IFERROR(E7/D7,0) -> -0.16594514
A8: 46204 | B8: ACA Individual | C8: 43791 | D8: 53002 | E8: =C8-D8 -> -9211 | F8: =IFERROR(E8/D8,0) -> -0.17378589
A9: 46235 | B9: ACA Individual | C9: 43504 | D9: 53107 | E9: =C9-D9 -> -9603 | F9: =IFERROR(E9/D9,0) -> -0.18082362
A10: 46266 | B10: ACA Individual | C10: 43291 | D10: 53211 | E10: =C10-D10 -> -9920 | F10: =IFERROR(E10/D10,0) -> -0.18642762
A11: 46023 | B11: Large Group | C11: 242603 | D11: 244741 | E11: =C11-D11 -> -2138 | F11: =IFERROR(E11/D11,0) -> -0.0087357656
A12: 46054 | B12: Large Group | C12: 243627 | D12: 245230 | E12: =C12-D12 -> -1603 | F12: =IFERROR(E12/D12,0) -> -0.0065367206
A13: 46082 | B13: Large Group | C13: 242475 | D13: 245720 | E13: =C13-D13 -> -3245 | F13: =IFERROR(E13/D13,0) -> -0.013206088
... A55: 46266 | B55: Small Group | C55: 53535 | D55: 55144 | E55: =C55-D55 -> -1609 | F55: =IFERROR(E55/D55,0) -> -0.029178152

Sheet Forecast
A1: month | B1: product | C1: actual_members | D1: forecast_members | E1: type | F1: variance | G1: variance_pct | H1: flag
A2: 46023 | B2: ACA Individual | C2: 46990 | D2: 51214 | E2: backtest | F2: -4224 | G2: -8.25 | H2: RESEARCH
A3: 46054 | B3: ACA Individual | C3: 45746 | D3: 50493 | E3: backtest | F3: -4747 | G3: -9.4 | H3: RESEARCH
A4: 46082 | B4: ACA Individual | C4: 44810 | D4: 49678 | E4: backtest | F4: -4868 | G4: -9.8 | H4: RESEARCH
A5: 46113 | B5: ACA Individual | C5: 44337 | D5: 49790 | E5: backtest | F5: -5453 | G5: -10.95 | H5: RESEARCH
A6: 46143 | B6: ACA Individual | C6: 44104 | D6: 49864 | E6: backtest | F6: -5760 | G6: -11.55 | H6: RESEARCH
A7: 46174 | B7: ACA Individual | C7: 44119 | D7: 50052 | E7: backtest | F7: -5933 | G7: -11.85 | H7: RESEARCH
A8: 46204 | B8: ACA Individual | C8: 43791 | D8: 50129 | E8: backtest | F8: -6338 | G8: -12.64 | H8: RESEARCH
A9: 46235 | B9: ACA Individual | C9: 43504 | D9: 50154 | E9: backtest | F9: -6650 | G9: -13.26 | H9: RESEARCH
A10: 46266 | B10: ACA Individual | C10: 43291 | D10: 50213 | E10: backtest | F10: -6922 | G10: -13.79 | H10: RESEARCH
A11: 46296 | B11: ACA Individual | D11: 43456 | E11: forecast
A12: 46327 | B12: ACA Individual | D12: 43476 | E12: forecast
A13: 46357 | B13: ACA Individual | D13: 43563 | E13: forecast
A14: 46388 | B14: ACA Individual | D14: 46103 | E14: forecast
A15: 46419 | B15: ACA Individual | D15: 45294 | E15: forecast
A16: 46447 | B16: ACA Individual | D16: 44454 | E16: forecast
A17: 46478 | B17: ACA Individual | D17: 44472 | E17: forecast
A18: 46508 | B18: ACA Individual | D18: 44486 | E18: forecast
A19: 46539 | B19: ACA Individual | D19: 44655 | E19: forecast
A20: 46569 | B20: ACA Individual | D20: 44673 | E20: forecast
A21: 46600 | B21: ACA Individual | D21: 44647 | E21: forecast
A22: 46631 | B22: ACA Individual | D22: 44670 | E22: forecast
... A25: 46722 | B25: ACA Individual | D25: 44942 | E25: forecast
A26: 46023 | B26: Large Group | C26: 242603 | D26: 242994 | E26: backtest | F26: -391 | G26: -0.16 | H26: OK
A27: 46054 | B27: Large Group | C27: 243627 | D27: 242656 | E27: backtest | F27: 971 | G27: 0.4 | H27: OK
A28: 46082 | B28: Large Group | C28: 242475 | D28: 243160 | E28: backtest | F28: -685 | G28: -0.28 | H28: OK
A29: 46113 | B29: Large Group | C29: 242372 | D29: 243081 | E29: backtest | F29: -709 | G29: -0.29 | H29: OK
A30: 46143 | B30: Large Group | C30: 243264 | D30: 243922 | E30: backtest | F30: -658 | G30: -0.27 | H30: OK
A31: 46174 | B31: Large Group | C31: 243805 | D31: 243513 | E31: backtest | F31: 292 | G31: 0.12 | H31: OK
A32: 46204 | B32: Large Group | C32: 242503 | D32: 244128 | E32: backtest | F32: -1625 | G32: -0.67 | H32: OK
A33: 46235 | B33: Large Group | C33: 243769 | D33: 244587 | E33: backtest | F33: -818 | G33: -0.33 | H33: OK
A34: 46266 | B34: Large Group | C34: 243580 | D34: 244496 | E34: backtest | F34: -916 | G34: -0.37 | H34: OK
A35: 46296 | B35: Large Group | D35: 243323 | E35: forecast
A36: 46327 | B36: Large Group | D36: 242992 | E36: forecast
A37: 46357 | B37: Large Group | D37: 243115 | E37: forecast
A38: 46388 | B38: Large Group | D38: 247518 | E38: forecast
A39: 46419 | B39: Large Group | D39: 247389 | E39: forecast
A40: 46447 | B40: Large Group | D40: 247376 | E40: forecast
A41: 46478 | B41: Large Group | D41: 247175 | E41: forecast
A42: 46508 | B42: Large Group | D42: 247931 | E42: forecast
...

Sheet Reconciliation
A1: month | B1: product | C1: region | D1: enrollment_members | E1: finance_members | F1: variance | G1: variance_pct | H1: status
A2: 2026-03-01 | B2: MA-PPO | C2: Philadelphia | D2: 21997 | E2: 20457 | F2: 1540 | G2: 7 | H2: RESEARCH
A3: 2026-06-01 | B3: ACA Individual | C3: Bucks | D3: 7059 | E3: 6847 | F3: 212 | G3: 3 | H3: RESEARCH
A4: 2026-06-01 | B4: ACA Individual | C4: Chester | D4: 6175 | E4: 5990 | F4: 185 | G4: 3 | H4: RESEARCH
A5: 2026-06-01 | B5: ACA Individual | C5: Delaware | D5: 7023 | E5: 6812 | F5: 211 | G5: 3 | H5: RESEARCH
A6: 2026-06-01 | B6: ACA Individual | C6: Montgomery | D6: 9247 | E6: 8970 | F6: 277 | G6: 3 | H6: RESEARCH
A7: 2026-06-01 | B7: ACA Individual | C7: Philadelphia | D7: 14615 | E7: 14177 | F7: 438 | G7: 3 | H7: RESEARCH

Sheet Lists
A1: month
A2: 44197
A3: 44228
A4: 44256
A5: 44287
A6: 44317
A7: 44348
A8: 44378
A9: 44409
A10: 44440
A11: 44470
A12: 44501
A13: 44531
... A70: 46266
